Workbook

Sheet Instruções
A1: INSTRUÇÕES DE USO
A2: Fluxo recomendado para aplicação, monitoramento e atualização do instrumento de controle da documentação escolar
A5: 1. Atualizar o cadastro | B5: Revisar os 217 registros de endereço e completar atos legais, vigência, responsáveis, data da atualização e observações cadastrais.
A6: 2. Planejar a verificação | B6: Criar ID único na aba Plano de Auditoria, selecionar a unidade, definir tipo, prioridade, datas e equipe responsável.
A7: 3. Avaliar os 53 registros | B7: Na Auditoria Documental, classificar cada item como Conforme, Parcialmente conforme, Não conforme, Não se aplica ou Não avaliado e indicar a evidência.
A8: 4. Aplicar a pontuação | B8: Conforme = 100% do peso; Parcialmente conforme = 50%; Não conforme/Não avaliado = 0%; Não se aplica = excluído mediante justificativa.
A9: 5. Usar a síntese da visita | B9: Os itens VIS-01 a VIS-12 reproduzem integralmente a última página do Checklist e alimentam automaticamente a aba Checklist da Visita.
A10: 6. Evitar dupla contagem | B10: Os 12 itens de síntese possuem peso zero. O índice global considera os 41 itens técnicos, preservando todos os registros sem duplicar sua influência estatística.
A11: 7. Tratar pendências | B11: Registrar no Plano de Ação cada não conformidade relevante, com prioridade, responsável, prazo, evidência e validação da CDE.
A12: 8. Monitorar resultados | B12: Utilizar Dashboard e Relatórios para reuniões de gestão, priorizando atos legais, vida escolar, arquivos, carga horária e divergências documentais.
A15: CRITÉRIOS DE CLASSIFICAÇÃO
A16: Situação | B16: Pontuação | C16: Significado | D16: Encaminhamento
A17: Conforme | B17: 100% do peso | C17: Evidência integral, válida e coerente. | D17: Manter e monitorar.
A18: Parcialmente conforme | B18: 50% do peso | C18: Atendimento incompleto ou evidência parcial. | D18: Complementar e registrar prazo.
A19: Não conforme | B19: 0% | C19: Ausência, invalidade ou divergência relevante. | D19: Abrir ação corretiva.
A20: Não se aplica | B20: Excluído | C20: Item incompatível com a oferta/situação da unidade. | D20: Justificar formalmente.
A23: FONTES INCORPORADAS AO INSTRUMENTO
A24: Checklist Coordenadoria de Documentação Escolar.pdf | B24: 53 registros incorporados integralmente: 41 itens técnicos e 12 itens do Checklist para a visita.
A25: Endereço de Unidades escolares por Distrito e_Bairro.xlsx | B25: 217 unidades incorporadas com distrito, bairro, vínculo, INEP, situação, tipo, endereço, CEP, telefone e e-mail.

Sheet Cadastro Unidades
A2: Base territorial unificada das unidades municipais e OSCs/conveniadas — organizada por distrito e bairro
A5: Distrito | B5: Bairro | C5: Rede/Vínculo | D5: Código INEP/MEC | E5: Nome da unidade | F5: Situação | G5: Tipo de unidade | H5: Distrito do anexo | I5: Tipo do prédio | J5: Tipo de contrato | K5: Zona | L5: Endereço | M5: Número | N5: Complemento | O5: CEP | P5: Telefone | Q5: E-mail | R5: Ato de criação | S5: Ato de autorização/credenciamento/reconhecimento | T5: Vigência do ato | U5: Diretor(a) | V5: Contato | W5: Matrícula | X5: Secretário(a) escolar | Y5: Matrícula 2 | Z5: Data da atualização | AA5: Observações cadastrais
A6: DABEL | B6: BATISTA CAMPOS | C6: MUNICIPAL | D6: 15548058 | E6: ESCOLA MUNICIPAL PROFESSORA MARIA AUXILIADORA MARTINS GONCALVES | F6: ATIVA | G6: SEDE | H6: DABEL | I6: MUNICIPAL | J6: ALUGUEL | K6: URBANA | L6: RUA SAO MIGUEL | M6: 557 | N6: ENTRE TUPINAMBS E APINAGS ENTRE TUPINAMBAS E APINAGES | O6: 66033112 | Q6: iris.santana@semec.belem.pa.gov.br | R6: DECRETO Nº 96.781/2020 - PMB, DE 21 DE JULHO DE 2020 | S6: NÃO LOCALIZADO NO SITE DO CME BELÉM | U6: IRIS CORREA SANTANA - | V6: 981994474 | W6: 0351229- 019 | X6: SEM SECRETARIO | Z6: 46265
A7: DABEL | B7: GUAMA | C7: MUNICIPAL | D7: 15040801 | E7: ANEXO BARAO DE MAMORE DA EM FRANCISCO DA SILVA NUNES | F7: ATIVA | G7: ANEXO | H7: DABEL | I7: MUNICIPAL | J7: ALUGUEL | K7: URBANA | L7: TRAVESSA QUATORZE DE ABRIL | M7: 2321 | N7: CASA | O7: 66063485 | Q7: upbaraodemamore@semec.belem.pa.gov.br | S7: 10/2025 - CME, DE 17/06/2025 | T7: 47650 | U7: CLAUDICEIA BAIA FERREIRA | V7: 982020921 | W7: 1859030- 014 | X7: SEM SECRETARIO | Z7: 46265
A8: DABEL | B8: JURUNAS | C8: MUNICIPAL | D8: 15040720 | E8: ESCOLA MUNICIPAL PROF MIGUEL PERNAMBUCO FILHO | F8: ATIVA | G8: SEDE | H8: DABEL | I8: MUNICIPAL | J8: PROPRIA | K8: URBANA | L8: AVENIDA ROBERTO CAMELIER | M8: 825 | N8: RUA NOVA E PSG SANTA TEREZA | O8: 66025455 | Q8: emeif.mpfilho@semec.pmb.pa.gov.br | S8: 072/2018 - CME, DE 18/12/2018 | T8: 44906 | U8: LADYANNA CHRISTINA DE LIMA | V8: 982634727 | W8: 0349127- 018 | X8: ELIANE SANTANA HOMEM | Y8: 0390950-017 | Z8: 46265
A9: DABEL | B9: MARCO | C9: MUNICIPAL | D9: 15040860 | E9: ANEXO CASA DA CRIANCA SANTA INES DA EM ALZIRA PERNAMBUCO | F9: ATIVA | G9: ANEXO | H9: DABEL | I9: MUNICIPAL | J9: ALUGUEL | K9: URBANA | L9: AVENIDA JOAO PAULO II | M9: 1725 | N9: CASA ENTRE TV. LOMAS VALENTINAS E TV. ENEAS PINHEIRO | O9: 66095495 | Q9: casadacriancastaines@semec.belem.pa.gov.br | S9: 58/2019 - CME, DE 20/12/2019 | T9: 44989 | U9: ANA DEISE PINTO DA SILVA | Z9: 46265
A10: DABEL | B10: MARCO | C10: OSC/CONVENIADA | D10: 15182754 | E10: CENTRO EDUCACIONAL ARTE DE EDUCAR OSC ANEXO INSTITUTO ACELERA AMAZONIA | F10: ATIVA | G10: ANEXO | J10: SUBVENÇÃO | K10: URBANA | L10: PASSAGEM LINDOLFO COLLOR | M10: 115 | O10: 66095310 | R10: OSC - NÃO NECESSITA ATO DE CRIAÇÃO | S10: NÃO LOCALIZADO NO SITE DO CME BELÉM | Z10: 46265
A11: DABEL | B11: MARCO | C11: MUNICIPAL | D11: 15040860 | E11: ESCOLA MUNICIPAL ALZIRA PERNAMBUCO | F11: ATIVA | G11: SEDE | H11: DABEL | I11: MUNICIPAL | J11: PROPRIA | K11: URBANA | L11: TRAVESSA PEREBEBUI | M11: 1995 | N11: ENTRE AV. DUQUE DE CAXIAS E VISC. DE INHAUMA | O11: 66095661 | S11: 58/2019 - CME, DE 20/12/2019 | T11: 44989 | U11: ROSEANE RODRIGUES SIQUEIRA | W11: 0347000- 010 | X11: ABELARDO BARROSO BRABO | Y11: 1954261-010 | Z11: 46265
A12: DABEL | B12: MARCO | C12: MUNICIPAL | D12: 15181677 | E12: ESCOLA MUNICIPAL LIONS CLUBE DE BELEM | F12: ATIVA | G12: SEDE | H12: DABEL | I12: MUNICIPAL | J12: COMODATO | K12: URBANA | L12: PASSAGEM SAO JOSE | M12: 8 | O12: 66095570 | Q12: cclionsclubedebelem@semec.belem.pa.gov.br | R12: DECRETO Nº 113.717/2025 - PMB, DE 23 DE JUNHO DE 2025 | S12: 22/2025 - CME, DE 09/09/2025 | T12: 46273 | U12: ROSANGELA PANTOJA MOTA | V12: 987325386 | W12: 0421820- 012 | X12: IZABEL SEIXAS DE OLIVEIRA | Y12: 0053821-017 | Z12: 46265
A13: DABEL | B13: MARCO | C13: MUNICIPAL | D13: 15547299 | E13: ESCOLA MUNICIPAL PROFESSORA LUCIA SOARES CASTRO | F13: ATIVA | G13: SEDE | H13: DABEL | I13: MUNICIPAL | J13: PROPRIA | K13: URBANA | L13: AVENIDA JOAO PAULO II | M13: 1538 | N13: ENTRE LOMAS E ANGUSTURA | O13: 66095494 | Q13: emeiluciacastro@gmail.com | R13: DECRETO Nº 96.504/2020 - PMB, DE 16 DE JUNHO DE 2020. | S13: 12/2022 - CME, DE 21/12/2022 | T13: 46741 | U13: LUCELINA DE SOUSA LIMA | V13: 981260269 | W13: 0347663- 010 | Z13: 46265
A14: DABEL | B14: MARCO | C14: MUNICIPAL | D14: 15174557 | E14: ESCOLA MUNICIPAL PROFESSORA RAIMUNDA LUCIA GUERREIRO | F14: ATIVA | G14: SEDE | H14: DABEL | I14: MUNICIPAL | J14: ALUGUEL | K14: URBANA | L14: TRAVESSA LOMAS VALENTINAS | M14: 2892 | N14: ENTRE JOAO PAULO E PASSAGEM PIO X | O14: 66093677 | Q14: profraimundaluciaguerreiro@semec.belem.pa.gov.br | R14: DECRETO Nº 96.325/2020 - PMB, DE 19 DE MAIO DE 2020, RETIFICADO PELO DECRETO Nº 96.503/2020 - PMB, DE 16/06/2020 | S14: 05/2023 - CME, DE 12/04/2023 | T14: 46854 | U14: AMANDA FERREIRA DA COSTA SA | V14: 982683788 | W14: 0348520- 018 | Z14: 46265
A15: DABEL | B15: MARCO | C15: MUNICIPAL | D15: 15040968 | E15: ESCOLA MUNICIPAL RUY DA SILVEIRA BRITTO | F15: ATIVA | G15: SEDE | H15: DABEL | I15: MUNICIPAL | J15: PROPRIA | K15: URBANA | L15: TRAVESSA DOUTOR ENEAS PINHEIRO | M15: 2871 | N15: ENTRE PERIMETRAL E JOAO PAULO II | O15: 66095015 | Q15: ruydasilveirabrito@semec.belem.pa.gov.br | S15: 04/2023 - CME, DE 12/04/2023 | T15: 46854 | U15: ROSEANE CONCEIÇÃO COUTO VOGADO | V15: 991890167 | W15: 1861417- 010 | X15: RONALDO XAVIER DE CARVALHO | Y15: 1882457-010 | Z15: 46265
A16: DABEL | B16: NAZARE | C16: MUNICIPAL | D16: 15176487 | E16: CENTRO DE REFERENCIA DE EDUCACAO INFANTIL PROF ORLANDO BITAR | F16: ATIVA | G16: SEDE | H16: DABEL | I16: MUNICIPAL | J16: PROPRIO | K16: URBANA | L16: AVENIDA GOVERNADOR JOSE MALCHER | M16: 793 | N16: ENTRE TV VISCONDE DE SOUZA FRANCO E TV QUINTINO BO | O16: 66055260 | Q16: crei.orlandobitar@semec.belem.pa.gov.br | S16: NÃO LOCALIZADO NO SITE DO CME BELÉM | U16: EDELRA DE JESUS NUNES DOS SANTOS | V16: 981158733 | W16: 0411353- 012 | Z16: 46265
A17: DABEL | B17: NAZARE | C17: OSC/CONVENIADA | D17: 15041743 | E17: INSTITUTO FELIPE SMALDONE BELEM | F17: ATIVA | G17: ESCOLA | H17: DABEL | I17: CEDIDO | J17: SUBVENÇÃO | K17: URBANA | L17: TRAVESSA QUATORZE DE MARCO | M17: 854 | O17: 66055490 | P17: 32229630 | R17: OSC - NÃO NECESSITA ATO DE CRIAÇÃO | S17: 048/2024 - CME, DE 11/12/2024 | T17: 47462 | Z17: 46265
A18: DABEL | B18: SAO BRAS | C18: OSC/CONVENIADA | D18: 15159477 | E18: CRECHE CASA LAR CORDEIRINHO DE DEUS | F18: ATIVA | G18: ESCOLA | H18: DABEL | I18: CEDIDO | J18: SUBVENÇÃO | K18: URBANA | L18: TRAVESSA FRANCISCO CALDEIRA CASTELO BRANCO | M18: 923 | O18: 66063000 | P18: 32497376 | R18: OSC - NÃO NECESSITA ATO DE CRIAÇÃO | S18: 39/2023 - CME, DE 13/12/2023 | T18: 46003 | Z18: 46265
A19: DABEL | B19: SAO BRAS | C19: MUNICIPAL | D19: 15040887 | E19: ESCOLA MUNICIPAL BENVINDA DE FRANCA MESSIAS | F19: ATIVA | G19: SEDE | H19: DABEL | I19: MUNICIPAL | J19: PROPRIA | K19: URBANA | L19: PRACA FLORIANO PEIXOTO | M19: 805 | O19: 66090290 | Q19: benvindadefrancamessias@semec.belem.pa.gov.br | S19: 025/2024 - CME, DE 19/06/2024 | T19: 47287 | U19: REGEANE CONCEIÇÃO ESTEVES DE LIMA | V19: 981144264 | W19: 0346535- 018 | X19: ELIETE DO SOCORRO KEMPER MAIA SOUZA | Y19: 0047287-012 | Z19: 46265
A20: DABEL | B20: SAO BRAS | C20: MUNICIPAL | D20: 15040909 | E20: ESCOLA MUNICIPAL ERNESTINA RODRIGUES | F20: ATIVA | G20: SEDE | H20: DABEL | I20: MUNICIPAL | J20: PROPRIA | K20: URBANA | L20: PASSAGEM ALBERTO ENGELHARD | M20: 286 | N20: PROX AO MUSEU EMILIO GOELD ENTRE MAGALHAES BARATA E GOV. JOSE MALCHER | O20: 66040520 | Q20: ernestinarodrigues@semec.belem.pa.gov.br | S20: 11/2026 - CME, DE 09/06/2026 | T20: 46546 | U20: CARLOS ALBERTO DOS SANTOS RAMOS | V20: 985805523 | W20: 1964267- 010 | X20: RAQUEL RODRIGUES DE MATOS VENTURA | Y20: 1983083-019 | Z20: 46265
A21: DABEL | B21: SAO BRAS | C21: MUNICIPAL | D21: 15040801 | E21: ESCOLA MUNICIPAL FRANCISCO DA SILVA NUNES | F21: ATIVA | G21: SEDE | H21: DABEL | I21: MUNICIPAL | J21: PROPRIO | K21: URBANA | L21: TRAVESSA FRANCISCO CALDEIRA CASTELO BRANCO | M21: 1824 | N21: SAO BRAZ PARIQUIS E CARIPUNAS | O21: 66063223 | Q21: franciscodasilvanunes@semec.belem.pa.gov.br | S21: 10/2025 - CME, DE 17/06/2025 | T21: 47650 | U21: ELIANA MARIA FERREIRA RIBEIRO MALATO | V21: 981570042 | W21: 0289426- 022 | X21: REGINA CELIA MELO DOS SANTOS | Y21: 0394556-011 | Z21: 46265
A22: DABEL | B22: TERRA FIRME | C22: MUNICIPAL | D22: 15040887 | E22: ANEXO SOLAR ACALANTO DA EM BENVINDA DE FRANCA MESSIAS | F22: ATIVA | G22: ANEXO | H22: DABEL | I22: MUNICIPAL | J22: ALUGUEL | K22: URBANA | L22: PASSAGEM INDEPENDENCIA | M22: 217 | N22: CONJ RESIDENCIAL RORAIMA | O22: 66070240 | S22: 025/2024 - CME, DE 19/06/2024 | T22: 47287 | U22: MAURICIO MAIA CERQUEIRA FILHO | V22: 982799894 | W22: 0346691- 010 | Z22: 46265
A23: DABEN | B23: BENGUI | C23: OSC/CONVENIADA | D23: 15174603 | E23: CENTRO COMUNITARIO NOSSA SENHORA DO PERPETUO SOCORRO | F23: ATIVA | G23: ESCOLA | H23: DABEL | I23: CEDIDO | J23: SUBVENÇÃO | K23: URBANA | L23: RUA OLAVO NUNES | M23: 74 | O23: 66630315 | P23: 32851977 | R23: OSC - NÃO NECESSITA ATO DE CRIAÇÃO | S23: 37/2023 - CME, DE 12/12/2023 | T23: 46003 | Z23: 46265
A24: DABEN | B24: BENGUI | C24: MUNICIPAL | D24: 15040640 | E24: ESCOLA MUNICIPAL AUGUSTO MEIRA FILHO | F24: ATIVA | G24: SEDE | H24: DABEN | I24: MUNICIPAL | J24: PROPRIA | K24: URBANA | L24: RUA LAMEIRA BITTENCOURT | M24: SN | N24: RUA SAO PEDRO E RUA BETANIA | O24: 66630010 | Q24: augusto-meiraf@semec.belem.pa.gov.br | R24: LEI Nº 7.183/1981 - PMB, DE 11/11/1981 | S24: 67/2019 - CME, DE 20/12/2019 | T24: 45242 | U24: ELIENE CAROLINA CHUCRE MACIEL ALBUQUERQUE | V24: 984297904 | W24: 0373478- 011 | X24: RODRIGO GOMES CEZAR DE SOUSA | Y24: 0427004-012 | Z24: 46265
A25: DABEN | B25: BENGUI | C25: MUNICIPAL | D25: 15040704 | E25: ESCOLA MUNICIPAL MARIA AMORAS DE OLIVEIRA | F25: ATIVA | G25: SEDE | H25: DABEN | I25: MUNICIPAL | J25: PROPRIA | K25: URBANA | L25: PASSAGEM SAO PEDRO | M25: SN | N25: PROXIMO A AJAX DE OLIVEIRA | O25: 66630390 | Q25: mariaamorasdeoliveira@semec.belem.pa.gov.br | S25: 10/2026 - CME, DE 09/06/2026 | T25: 47277 | U25: LAURIMAR DE MATOS FARIAS | V25: 981726775 | W25: 0027995- 011 | X25: CARLOS ANTONIO DE SOUZA RODRRIGUES | Y25: 0390518-018 | Z25: 46265
A26: DABEN | B26: BENGUI | C26: MUNICIPAL | D26: 15543234 | E26: ESCOLA MUNICIPAL PROFESSORA ANGELICA DO CARMO SANTOS PAIVA | F26: ATIVA | G26: SEDE | H26: DABEN | I26: MUNICIPAL | J26: PROPRIA | K26: URBANA | L26: RUA SAO BENTO | M26: 70 | N26: PROX. MERCADO NOVO ENTRE MAJ MIGUEL E SANTA MARIA | O26: 66630030 | Q26: profangelicadocarmosantospaiva@semec.belem.pa.gov | R26: DECRETO Nº 95.488/2020 - PMB, DE 03 DE FEVEREIRO DE 2020 | S26: 19/2023 - CME, DE 18/10/2023 | T26: 47043 | U26: JOSILAINE PARAGUASSU PINTO DA SILVA | V26: 985470707 | W26: 0370894- 014 | Z26: 46265
A27: DABEN | B27: BENGUI | C27: MUNICIPAL | D27: 15170853 | E27: ESCOLA MUNICIPAL PROFESSORA GILVANIA MARCIA BARROS DA SILVA | F27: ATIVA | G27: SEDE | H27: DABEN | I27: MUNICIPAL | J27: PROPRIA | K27: URBANA | L27: RUA SAO CLEMENTE | M27: S/N | N27: PASSAGEM PRATINHA | O27: 66630080 | Q27: gilvaniamarciabarrosdasilva@semec.belem.pa.gov.br | R27: DECRETO Nº 89.868/2017 - PMB, DE 2 DE OUTUBRO DE 2017 | S27: 15/2025 - CME, DE 17/06/2025 | T27: 47650 | U27: ELAINE CRISTINE RODRIGUES PEREIRA MENDES | V27: 982942476 | W27: 0348236- 018 | Z27: 46265
A28: DABEN | B28: BENGUI | C28: OSC/CONVENIADA | D28: 15574172 | E28: INSTITUTO UNIDOS VENCEREMOS | F28: ATIVA | G28: ESCOLA | H28: DABEN | I28: CEDIDO | J28: SUBVENÇÃO | K28: URBANA | L28: PASSAGEM SAO JOSE | M28: 25294 | O28: 66630215 | P28: 32237547 | R28: OSC - NÃO NECESSITA ATO DE CRIAÇÃO | S28: 09/2025 - CME, DE 06/05/2025 | T28: 46512 | Z28: 46265
A29: DABEN | B29: CABANAGEM | C29: OSC/CONVENIADA | D29: 15173860 | E29: CENTRO EDUCACIONAL DE ENSINO INFANTIL MUNDO ENCANTADO | F29: ATIVA | G29: ESCOLA | H29: DABEN | I29: CEDIDO | J29: SUBVENÇÃO | K29: URBANA | L29: RUA SAO PAULO | M29: 30 | O29: 66625490 | P29: 83354855 | R29: OSC - NÃO NECESSITA ATO DE CRIAÇÃO | S29: 35/2023 - CME, DE 22/11/2023 | T29: 45982 | Z29: 46265
A30: DABEN | B30: CABANAGEM | C30: OSC/CONVENIADA | D30: 15182258 | E30: CENTRO EDUCACIONAL EU AMO EU CUIDO | F30: ATIVA | G30: ESCOLA | H30: DABEN | I30: CEDIDO | J30: SUBVENÇÃO | K30: URBANA | L30: ALAMEDA ADRIANO ANDRADE | M30: 6 | O30: 66625140 | R30: OSC - NÃO NECESSITA ATO DE CRIAÇÃO | S30: NÃO LOCALIZADO NO SITE DO CME BELÉM | Z30: 46265
A31: DABEN | B31: CABANAGEM | C31: MUNICIPAL | D31: 15535827 | E31: ESCOLA MUNICIPAL DEPUTADO JOAO CARLOS BATISTA | F31: ATIVA | G31: SEDE | H31: DABEN | I31: MUNICIPAL | J31: PROPRIA | K31: URBANA | L31: TRAVESSA CRISTINA CARDOSO | M31: S/N | N31: ENTRE AV INDEPENDENCIA E RUA BELEM | O31: 66625630 | Q31: deputadojoaocarlosbatista@semec.belem.pa.gov.br | S31: 040/2024 - CME, DE 23/10/2024 | T31: 47413 | U31: MARIA GORETTI DE JESUS CARNEIRO | V31: 991114184 | W31: 0048550- 035 | X31: SILVANA PIMENTEL BORGES | Y31: 2008394-012 | Z31: 46265
A32: DABEN | B32: COQUEIRO | C32: MUNICIPAL | D32: 15181642 | E32: ESCOLA MUNICIPAL ALANA DE SOUZA BARBOSA I | F32: ATIVA | G32: SEDE | H32: DABEN | I32: MUNICIPAL | J32: ALUGUEL | K32: URBANA | L32: ALAMEDA PRIMAVERA | M32: 20 | N32: CONJ ARIRI BOLONHA QUADRA 26 RL 09 L 22 | O32: 66650507 | Q32: alanadesouzabarboza1@semec.belem.pa.gov.br | R32: DECRETO N.º 113.730/2025 – PMB, DE 23 DE JUNHO DE 2025 | S32: 22/2025 - CME, DE 09/09/2025 | T32: 46273 | U32: KATIANE DO ROSARIO CORREA BARBOSA | V32: 988079826 | W32: 0273511- 025 | X32: ROSANGELA VIEIRA DE ARAUJO | Y32: 1996843-017 | Z32: 46265
A33: DABEN | B33: COQUEIRO | C33: MUNICIPAL | D33: 15181863 | E33: ESCOLA MUNICIPAL ALANA DE SOUZA BARBOSA II | F33: ATIVA | G33: SEDE | H33: DABEN | I33: MUNICIPAL | J33: ALUGUEL | K33: URBANA | L33: RUA ESPERANTISTA | M33: 4 | O33: 66650600 | Q33: escolaanexa2alana@gmail.com | R33: DECRETO N.º 113.731/2025 – PMB, DE 23 DE JUNHO DE 2025 | S33: 22/2025 - CME, DE 09/09/2025 | T33: 46273 | U33: SANDRA MARIA PANTOJA PINTO | V33: 984115800 | W33: 0351644- 016 | X33: REGIANE RIBEIRO TEÓFILO | Y33: 0423351-028 | Z33: 46265
A34: DABEN | B34: COQUEIRO | C34: MUNICIPAL | D34: 15181685 | E34: ESCOLA MUNICIPAL CRISTO REDENTOR | F34: ATIVA | G34: SEDE | H34: DABEN | I34: MUNICIPAL | J34: ALUGUEL | K34: URBANA | L34: PASSAGEM COMERCIARIOS | M34: 108 | O34: 66650550 | Q34: cristoredentor@semec.belem.pa.gov.br | R34: DECRETO N.º 113.720/2025 – PMB, DE 23 DE JUNHO DE 2025 | S34: 22/2025 - CME, DE 09/09/2025 | T34: 46273 | U34: SHEILA ALVES DE ARAUJO | V34: 986505858 | W34: 0574058- 010 | X34: IRENILDA MONTEIRO MCHADO | Y34: 0431699-011 | Z34: 46265
A35: DABEN | B35: COQUEIRO | C35: MUNICIPAL | D35: 15169979 | E35: ESCOLA MUNICIPAL PADRE BRUNO SECHI | F35: ATIVA | G35: SEDE | H35: DABEN | I35: MUNICIPAL | J35: PROPRIA | K35: URBANA | L35: TRAVESSA WE 8 | M35: S/N | N35: AO LADO DA UNIDADE DE SAUDE | O35: 66670220 | Q35: pebrunosechi@semec.belem.pa.gov.br | R35: DECRETO Nº 113.110/2024 - PMB, DE 23 DE DEZEMBRO DE 2024 | S35: 22/2025 - CME, DE 09/09/2025 | T35: 46273 | U35: VANESSA MACHADO DE ANDRADE | V35: 982094242 | W35: 0347205- 011 | X35: NEMESIO LOPES MONTEIRO JUNIOR | Y35: 1836340-017 | Z35: 46265
A36: DABEN | B36: COQUEIRO | C36: MUNICIPAL | D36: 15223000 | E36: ESCOLA MUNICIPAL PROFESSORA ALANA DE SOUZA BARBOZA | F36: ATIVA | G36: SEDE | H36: DABEN | I36: MUNICIPAL | J36: PROPRIA | K36: URBANA | L36: QUADRA VINTE E SETE | N36: ESQ ESPERANTISTA | O36: 66650185 | Q36: alanasouzabarboza@semec.belem.pa.gov.br | R36: PORTARIA Nº. 1.313/2008 - GABS, DE 08 DE OUUBRO DE 2008 | S36: 042/2024 - CME, DE 23/10/2024 | T36: 47413 | U36: EULINA DOMINGUES LOPES | V36: 985382828 | W36: 0411310- 011 | X36: LIA DA COSTA TAVARES ATAIDE | Y36: 0391050-010 | Z36: 46265
A37: DABEN | B37: COQUEIRO | C37: MUNICIPAL | D37: 15164160 | E37: ESCOLA MUNICIPAL SAO GASPAR | F37: ATIVA | G37: SEDE | H37: DABEN | I37: MUNICIPAL | J37: ALUGUEL | K37: URBANA | L37: RUA B | M37: 61 | N37: CONJUNTO PEDRO TEIXEIRA EM FRENTE A ESCOLA 7 ANOS | O37: 66670070 | Q37: saogaspar@semec.belem.pa.gov.br | R37: PORTARIA Nº. 1.030/2014 - GABS, DE 23 DE ABRIL DE 2014 | S37: 12/2025 - CME, DE 17/06/2025 | T37: 47650 | U37: GIRLANE LOURENÇO DOS SANTOS | V37: 982444884 | W37: 0410551- 015 | Z37: 46265
A38: DABEN | B38: COQUEIRO | C38: MUNICIPAL | D38: 15558363 | E38: ESCOLA MUNICIPAL SILVIO LEANDRO | F38: ATIVA | G38: SEDE | H38: DABEN | I38: MUNICIPAL | J38: PROPRIA | K38: URBANA | L38: RODOVIA MARIO COVAS | M38: SN | N38: ESQ PASSAGEM COIMBRA | O38: 66670000 | Q38: silvioleandro@semec.belem.pa.gov.br | S38: 012/2024 - CME, DE 15/05/2024 | T38: 46887 | U38: PAULA ROBERTA DE JESUS MONTEIRO | V38: 982284941 | W38: 0422754- 013 | X38: DOMINGAS RAQUEL GONÇALVES MEDEIROS | Y38: 0390364-010 | Z38: 46265
A39: DABEN | B39: MANGUEIRAO | C39: OSC/CONVENIADA | D39: 15159469 | E39: ASSOCIACAO BENEFICENTE SAO CARLOS DO BRASIL | F39: ATIVA | G39: ESCOLA | H39: DABEN | I39: CEDIDO | J39: SUBVENÇÃO | K39: URBANA | L39: AVENIDA MANGUEIRAO | M39: 32 | O39: 66640480 | P39: 87291508 | R39: OSC - NÃO NECESSITA ATO DE CRIAÇÃO | S39: 32/2023 - CME, DE 22/11/2023 | T39: 45982 | Z39: 46265
A40: DABEN | B40: MANGUEIRAO | C40: MUNICIPAL | D40: 15543285 | E40: ESCOLA MUNICIPAL CATALINA I | F40: ATIVA | G40: SEDE | H40: DABEN | I40: MUNICIPAL | J40: PROPRIA | K40: URBANA | L40: TRAVESSA QUATRO | M40: SN | N40: CONJ. CATALINA | O40: 66640290 | Q40: catalina1@semec.belem.pa.gov.br | R40: PORTARIA Nº 547 / 2007 – PMB, DE 28 DE MAIO DE 2007 | S40: 24/2025 - CME, DE 21/10/2025 | T40: 47776 | U40: ROSANGELA ALBELIA RODRIGUES RABELO | V40: 983003058 | W40: 0248380- 036 | Z40: 46265
A41: DABEN | B41: MANGUEIRAO | C41: MUNICIPAL | D41: 15558347 | E41: ESCOLA MUNICIPAL CATALINA II | F41: ATIVA | G41: SEDE | H41: DABEN | I41: MUNICIPAL | J41: PROPRIA | K41: URBANA | L41: QUADRA NOVE | M41: SN | N41: AVENIDA CENTENARIO COM SG FAVARO CJ CATALINA | O41: 66640642 | Q41: catalina2@semec.belem.pa.gov.br | R41: PORTARIA Nº 548 / 2007 – PMB, DE 28 DE MAIO DE 2007 | S41: 08/2026 - CME, DE 09/06/2026 | T41: 48007 | U41: NAYARA ARAUJO DA COSTA FIGUEIREDO | V41: 989940628 | W41: 0566420- 015 | Z41: 46265
A42: DABEN | B42: MANGUEIRAO | C42: MUNICIPAL | D42: 15152324 | E42: ESCOLA MUNICIPAL CATALINA III | F42: ATIVA | G42: SEDE | H42: DABEN | I42: MUNICIPAL | J42: PROPRIA | K42: URBANA | L42: TRAVESSA SARGENTO FAVARRO | M42: SN | N42: TV. 15 CEL. AVIADOR BRITO TRAVESSA 15 | O42: 66640200 | Q42: catalina3@semec.belem.pa.gov.br | R42: PORTARIA Nº 549 / 2007 – PMB, DE 28 DE MAIO DE 2007 | S42: 06/2024 - CME, DE 21/02/2024 | T42: 47169 | U42: SINARA BERNARDO DIAS | V42: 984184444 | W42: 0348880- 014 | Z42: 46265
A43: DABEN | B43: MANGUEIRAO | C43: MUNICIPAL | D43: 15043088 | E43: ESCOLA MUNICIPAL WALTER LEITE CAMINHA | F43: ATIVA | G43: SEDE | H43: DABEN | I43: MUNICIPAL | J43: PROPRIA | K43: URBANA | L43: AVENIDA MAJOR AVIADOR SILVA FILHO | M43: SN | N43: CJ CATALINA TENENTE AVIADOR BRITO | O43: 66640220 | Q43: emef.walterleite@semec.belem.pa.gov.br | S43: 13/2025 - CME, DE 17/06/2025 | T43: 47650 | U43: RUTE RAIOL COSTA | V43: 980165440 | X43: MARCIA REGINA SOUZA CORDEIRO | Y43: 1992031-018 | Z43: 46265
...

Sheet DistritoBairro

Sheet Lista Mestra
A1: LISTA MESTRA — CHECKLIST DA DOCUMENTAÇÃO ESCOLAR
A2: Transcrição operacional integral dos 53 registros do Checklist da Coordenadoria de Documentação Escolar
A4: Os 41 itens técnicos recebem peso conforme a criticidade. Os 12 itens do Checklist da Visita têm natureza de síntese e peso zero, evitando a duplicação estatística dos mesmos controles.
A6: Código | B6: Seção do Checklist | C6: Documento/item de controle | D6: Evidência mínima | E6: Abrangência/periodicidade | F6: Criticidade | G6: Peso | H6: Origem no Checklist | I6: Responsável primário | J6: Orientação de conferência
A7: INS-01 | B7: 1. Documentos institucionais | C7: Ato de criação da escola | D7: Ato integral, legível e disponível para conferência. | E7: Vigência e anterior | F7: Crítica | G7: 3 | H7: Checklist CDE — item 1.1 | I7: Gestão/Secretaria | J7: Conferir número, data, órgão emissor e denominação da unidade.
A8: INS-02 | B8: 1. Documentos institucionais | C8: Recibo do Censo Escolar (Autorização) | D8: Recibo do Censo Escolar e comprovantes correspondentes. | E8: Vigência e anterior | F8: Alta | G8: 2 | H8: Checklist CDE — item 1.2 | I8: Secretaria | J8: Conciliar o recibo com o período, as matrículas, turmas e etapas declaradas.
A9: INS-03 | B9: 1. Documentos institucionais | C9: Ato de autorização, credenciamento ou reconhecimento | D9: Ato completo, vigente e compatível com as etapas/modalidades ofertadas. | E9: Vigência e anterior | F9: Crítica | G9: 3 | H9: Checklist CDE — item 1.3 | I9: Gestão | J9: Conferir número, data, vigência, órgão emissor e abrangência.
A10: INS-04 | B10: 1. Documentos institucionais | C10: Regimento Escolar atualizado | D10: Versão atualizada, aprovada, datada e disponível. | E10: Vigência e anterior | F10: Alta | G10: 2 | H10: Checklist CDE — item 1.4 | I10: Gestão | J10: Verificar aprovação, atualização e coerência com a organização escolar.
A11: INS-05 | B11: 1. Documentos institucionais | C11: Projeto Político-Pedagógico (PPP) | D11: PPP atualizado, aprovado e disponível. | E11: Vigência e anterior | F11: Alta | G11: 2 | H11: Checklist CDE — item 1.5 | I11: Gestão/Coordenação | J11: Conferir diagnóstico, objetivos, organização pedagógica, metas e atualização.
A12: INS-06 | B12: 1. Documentos institucionais | C12: Calendário Escolar vigente | D12: Calendário acessível no SIGA: Administração > Calendário Escolar > Acessar Calendário. | E12: Vigência e anterior | F12: Alta | G12: 2 | H12: Checklist CDE — item 1.6 | I12: Gestão/Secretaria | J12: Conferir aprovação, dias letivos, carga horária e eventuais reposições.
A13: INS-07 | B13: 1. Documentos institucionais | C13: Matriz curricular, inclusive cursos técnicos | D13: Matriz vigente por etapa/modalidade, com componentes e cargas horárias. | E13: Vigência e anterior | F13: Crítica | G13: 3 | H13: Checklist CDE — item 1.7 | I13: Coordenação/Secretaria | J13: Conciliar com horários, diários, resultados e documentos expedidos.
A14: SEC-01 | B14: 2. Secretaria escolar | C14: Livro de Matrícula | D14: Livro completo, atualizado e com termos de abertura e encerramento. | E14: Vigência e anterior | F14: Crítica | G14: 3 | H14: Checklist CDE — item 2.1 | I14: Secretaria | J14: Conciliar com fichas de matrícula, turmas e sistema informatizado.
A15: SEC-02 | B15: 2. Secretaria escolar | C15: Livro de Atas — resultados finais, Conselho de Classe, reuniões e outros | D15: Livros completos, sequenciais, datados e assinados. | E15: Vigência e anterior | F15: Crítica | G15: 3 | H15: Checklist CDE — item 2.2 | I15: Gestão/Secretaria | J15: Verificar resultados, deliberações, participantes, datas e assinaturas.
A16: SEC-03 | B16: 2. Secretaria escolar | C16: Livro de Registro de Diplomas e Certificados, quando aplicável | D16: Registro sequencial, íntegro e rastreável dos documentos expedidos. | E16: Vigência e anterior | F16: Crítica | G16: 3 | H16: Checklist CDE — item 2.3 | I16: Secretaria | J16: Conciliar numeração, estudante, curso, data e documento arquivado.
A17: SEC-04 | B17: 2. Secretaria escolar | C17: Protocolos de entrada e saída de documentos | D17: Registros cronológicos de recebimento, tramitação e entrega. | E17: Vigência e anterior | F17: Alta | G17: 2 | H17: Checklist CDE — item 2.4 | I17: Secretaria | J17: Conferir número, data, interessado, assunto, destino e recebimento.
A18: SEC-05 | B18: 2. Secretaria escolar | C18: Arquivo ativo e arquivo permanente organizados | D18: Pastas classificadas, preservadas, localizáveis e com acesso controlado. | E18: Vigência e anterior | F18: Crítica | G18: 3 | H18: Checklist CDE — item 2.5 | I18: Gestão/Secretaria | J18: Verificar integridade, ordenação, conservação, índice e proteção dos dados.
... A59: VIS-12 | B59: 7. Checklist da visita | C59: Dados do Censo Escolar conferidos | D59: Síntese de conferência da visita. | E59: Na visita | F59: Síntese | G59: 0 | H59: Checklist para a visita — item 12 | I59: Equipe de visita | J59: Conciliar dados declarados com os registros escolares.

Sheet Plano de Auditoria
A1: PLANO DE AUDITORIA DOCUMENTAL
A2: Programação, execução e consolidação das verificações por unidade educacional
A5: ID auditoria | B5: Unidade | C5: Distrito | D5: Tipo de verificação | E5: Prioridade | F5: Data planejada | G5: Data realizada | H5: Auditor(a)/equipe | I5: Situação | J5: Itens previstos | K5: Itens avaliados | L5: Índice ponderado | M5: NC críticas | N5: Checklist da visita concluído | O5: Observações
A6: AUD-001 | B6: ESCOLA MUNICIPAL PROFESSORA MARIA AUXILIADORA MARTINS GONCALVES | C6: {=IF(B6="","",IFERROR(INDEX('Cadastro Unidades'!$A$6:$A$222,MATCH(B6,'Cadastro Unidades'!$E$6:$E$222,0)),""))} -> DABEL | D6: Acompanhamento de pendências | E6: Alta | I6: Planejada | J6: =IF(A7="","",COUNTIF('Auditoria Documental'!$A$7:$A$1000,A7)) -> 0 | K6: =IF(A7="","",COUNTIFS('Auditoria Documental'!$A$7:$A$1000,A7,'Auditoria Documental'!$K$7:$K$1000,"<>Não avaliado",'Auditoria Documental'!$K$7:$K$1000,"<>")) -> 0 | L6: =IF(A7="","",IFERROR(SUMIFS('Auditoria Documental'!$N$7:$N$1000,'Auditoria Documental'!$A$7:$A$1000,A7)/SUMIFS('Auditoria Documental'!$M$7:$M$1000,'Auditoria Documental'!$A$7:$A$1000,A7),0)) -> 0 | M6: =IF(A7="","",COUNTIFS('Auditoria Documental'!$A$7:$A$1000,A7,'Auditoria Documental'!$J$7:$J$1000,3,'Auditoria Documental'!$K$7:$K$1000,"Não conforme")) -> 0 | N6: =IF(A7="","",IFERROR(COUNTIFS('Auditoria Documental'!$A$7:$A$1000,A7,'Auditoria Documental'!$G$7:$G$1000,"7. Checklist da visita",'Auditoria Documental'!$K$7:$K$1000,"<>Não avaliado",'Auditoria Documental'!$K$7:$K$1000,"<>")/COUNTIF('Lista Mestra'!$B$7:$B$59,"7. Checklist da visita"),0)) -> 0
A7: AUD-002 | B7: ANEXO BARAO DE MAMORE DA EM FRANCISCO DA SILVA NUNES | C7: {=IF(B7="","",IFERROR(INDEX('Cadastro Unidades'!$A$6:$A$222,MATCH(B7,'Cadastro Unidades'!$E$6:$E$222,0)),""))} -> DABEL | D7: Acompanhamento de pendências | J7: =IF(#REF!="","",COUNTIF('Auditoria Documental'!$A$7:$A$1000,#REF!)) -> #REF! | K7: =IF(#REF!="","",COUNTIFS('Auditoria Documental'!$A$7:$A$1000,#REF!,'Auditoria Documental'!$K$7:$K$1000,"<>Não avaliado",'Auditoria Documental'!$K$7:$K$1000,"<>")) -> #REF! | L7: =IF(#REF!="","",IFERROR(SUMIFS('Auditoria Documental'!$N$7:$N$1000,'Auditoria Documental'!$A$7:$A$1000,#REF!)/SUMIFS('Auditoria Documental'!$M$7:$M$1000,'Auditoria Documental'!$A$7:$A$1000,#REF!),0)) -> #REF! | M7: =IF(#REF!="","",COUNTIFS('Auditoria Documental'!$A$7:$A$1000,#REF!,'Auditoria Documental'!$J$7:$J$1000,3,'Auditoria Documental'!$K$7:$K$1000,"Não conforme")) -> #REF! | N7: =IF(#REF!="","",IFERROR(COUNTIFS('Auditoria Documental'!$A$7:$A$1000,#REF!,'Auditoria Documental'!$G$7:$G$1000,"7. Checklist da visita",'Auditoria Documental'!$K$7:$K$1000,"<>Não avaliado",'Auditoria Documental'!$K$7:$K$1000,"<>")/COUNTIF('Lista Mestra'!$B$7:$B$59,"7. Checklist da visita"),0)) -> #REF!
A8: AUD-003 | B8: ESCOLA MUNICIPAL PROF MIGUEL PERNAMBUCO FILHO | C8: {=IF(B8="","",IFERROR(INDEX('Cadastro Unidades'!$A$6:$A$222,MATCH(B8,'Cadastro Unidades'!$E$6:$E$222,0)),""))} -> DABEL | J8: =IF(A8="","",COUNTIF('Auditoria Documental'!$A$7:$A$1000,A8)) -> 0 | K8: =IF(A8="","",COUNTIFS('Auditoria Documental'!$A$7:$A$1000,A8,'Auditoria Documental'!$K$7:$K$1000,"<>Não avaliado",'Auditoria Documental'!$K$7:$K$1000,"<>")) -> 0 | L8: =IF(A8="","",IFERROR(SUMIFS('Auditoria Documental'!$N$7:$N$1000,'Auditoria Documental'!$A$7:$A$1000,A8)/SUMIFS('Auditoria Documental'!$M$7:$M$1000,'Auditoria Documental'!$A$7:$A$1000,A8),0)) -> 0 | M8: =IF(A8="","",COUNTIFS('Auditoria Documental'!$A$7:$A$1000,A8,'Auditoria Documental'!$J$7:$J$1000,3,'Auditoria Documental'!$K$7:$K$1000,"Não conforme")) -> 0 | N8: =IF(A8="","",IFERROR(COUNTIFS('Auditoria Documental'!$A$7:$A$1000,A8,'Auditoria Documental'!$G$7:$G$1000,"7. Checklist da visita",'Auditoria Documental'!$K$7:$K$1000,"<>Não avaliado",'Auditoria Documental'!$K$7:$K$1000,"<>")/COUNTIF('Lista Mestra'!$B$7:$B$59,"7. Checklist da visita"),0)) -> 0
A9: AUD-004 | B9: ANEXO CASA DA CRIANCA SANTA INES DA EM ALZIRA PERNAMBUCO | C9: {=IF(B9="","",IFERROR(INDEX('Cadastro Unidades'!$A$6:$A$222,MATCH(B9,'Cadastro Unidades'!$E$6:$E$222,0)),""))} -> DABEL | J9: =IF(A9="","",COUNTIF('Auditoria Documental'!$A$7:$A$1000,A9)) -> 0 | K9: =IF(A9="","",COUNTIFS('Auditoria Documental'!$A$7:$A$1000,A9,'Auditoria Documental'!$K$7:$K$1000,"<>Não avaliado",'Auditoria Documental'!$K$7:$K$1000,"<>")) -> 0 | L9: =IF(A9="","",IFERROR(SUMIFS('Auditoria Documental'!$N$7:$N$1000,'Auditoria Documental'!$A$7:$A$1000,A9)/SUMIFS('Auditoria Documental'!$M$7:$M$1000,'Auditoria Documental'!$A$7:$A$1000,A9),0)) -> 0 | M9: =IF(A9="","",COUNTIFS('Auditoria Documental'!$A$7:$A$1000,A9,'Auditoria Documental'!$J$7:$J$1000,3,'Auditoria Documental'!$K$7:$K$1000,"Não conforme")) -> 0 | N9: =IF(A9="","",IFERROR(COUNTIFS('Auditoria Documental'!$A$7:$A$1000,A9,'Auditoria Documental'!$G$7:$G$1000,"7. Checklist da visita",'Auditoria Documental'!$K$7:$K$1000,"<>Não avaliado",'Auditoria Documental'!$K$7:$K$1000,"<>")/COUNTIF('Lista Mestra'!$B$7:$B$59,"7. Checklist da visita"),0)) -> 0
A10: AUD-005 | B10: CENTRO EDUCACIONAL ARTE DE EDUCAR OSC ANEXO INSTITUTO ACELERA AMAZONIA | C10: {=IF(B10="","",IFERROR(INDEX('Cadastro Unidades'!$A$6:$A$222,MATCH(B10,'Cadastro Unidades'!$E$6:$E$222,0)),""))} -> DABEL | J10: =IF(A10="","",COUNTIF('Auditoria Documental'!$A$7:$A$1000,A10)) -> 0 | K10: =IF(A10="","",COUNTIFS('Auditoria Documental'!$A$7:$A$1000,A10,'Auditoria Documental'!$K$7:$K$1000,"<>Não avaliado",'Auditoria Documental'!$K$7:$K$1000,"<>")) -> 0 | L10: =IF(A10="","",IFERROR(SUMIFS('Auditoria Documental'!$N$7:$N$1000,'Auditoria Documental'!$A$7:$A$1000,A10)/SUMIFS('Auditoria Documental'!$M$7:$M$1000,'Auditoria Documental'!$A$7:$A$1000,A10),0)) -> 0 | M10: =IF(A10="","",COUNTIFS('Auditoria Documental'!$A$7:$A$1000,A10,'Auditoria Documental'!$J$7:$J$1000,3,'Auditoria Documental'!$K$7:$K$1000,"Não conforme")) -> 0 | N10: =IF(A10="","",IFERROR(COUNTIFS('Auditoria Documental'!$A$7:$A$1000,A10,'Auditoria Documental'!$G$7:$G$1000,"7. Checklist da visita",'Auditoria Documental'!$K$7:$K$1000,"<>Não avaliado",'Auditoria Documental'!$K$7:$K$1000,"<>")/COUNTIF('Lista Mestra'!$B$7:$B$59,"7. Checklist da visita"),0)) -> 0
A11: AUD-006 | B11: ESCOLA MUNICIPAL ALZIRA PERNAMBUCO | C11: {=IF(B11="","",IFERROR(INDEX('Cadastro Unidades'!$A$6:$A$222,MATCH(B11,'Cadastro Unidades'!$E$6:$E$222,0)),""))} -> DABEL | J11: =IF(A11="","",COUNTIF('Auditoria Documental'!$A$7:$A$1000,A11)) -> 0 | K11: =IF(A11="","",COUNTIFS('Auditoria Documental'!$A$7:$A$1000,A11,'Auditoria Documental'!$K$7:$K$1000,"<>Não avaliado",'Auditoria Documental'!$K$7:$K$1000,"<>")) -> 0 | L11: =IF(A11="","",IFERROR(SUMIFS('Auditoria Documental'!$N$7:$N$1000,'Auditoria Documental'!$A$7:$A$1000,A11)/SUMIFS('Auditoria Documental'!$M$7:$M$1000,'Auditoria Documental'!$A$7:$A$1000,A11),0)) -> 0 | M11: =IF(A11="","",COUNTIFS('Auditoria Documental'!$A$7:$A$1000,A11,'Auditoria Documental'!$J$7:$J$1000,3,'Auditoria Documental'!$K$7:$K$1000,"Não conforme")) -> 0 | N11: =IF(A11="","",IFERROR(COUNTIFS('Auditoria Documental'!$A$7:$A$1000,A11,'Auditoria Documental'!$G$7:$G$1000,"7. Checklist da visita",'Auditoria Documental'!$K$7:$K$1000,"<>Não avaliado",'Auditoria Documental'!$K$7:$K$1000,"<>")/COUNTIF('Lista Mestra'!$B$7:$B$59,"7. Checklist da visita"),0)) -> 0
A12: AUD-007 | B12: ESCOLA MUNICIPAL LIONS CLUBE DE BELEM | C12: {=IF(B12="","",IFERROR(INDEX('Cadastro Unidades'!$A$6:$A$222,MATCH(B12,'Cadastro Unidades'!$E$6:$E$222,0)),""))} -> DABEL | J12: =IF(A12="","",COUNTIF('Auditoria Documental'!$A$7:$A$1000,A12)) -> 0 | K12: =IF(A12="","",COUNTIFS('Auditoria Documental'!$A$7:$A$1000,A12,'Auditoria Documental'!$K$7:$K$1000,"<>Não avaliado",'Auditoria Documental'!$K$7:$K$1000,"<>")) -> 0 | L12: =IF(A12="","",IFERROR(SUMIFS('Auditoria Documental'!$N$7:$N$1000,'Auditoria Documental'!$A$7:$A$1000,A12)/SUMIFS('Auditoria Documental'!$M$7:$M$1000,'Auditoria Documental'!$A$7:$A$1000,A12),0)) -> 0 | M12: =IF(A12="","",COUNTIFS('Auditoria Documental'!$A$7:$A$1000,A12,'Auditoria Documental'!$J$7:$J$1000,3,'Auditoria Documental'!$K$7:$K$1000,"Não conforme")) -> 0 | N12: =IF(A12="","",IFERROR(COUNTIFS('Auditoria Documental'!$A$7:$A$1000,A12,'Auditoria Documental'!$G$7:$G$1000,"7. Checklist da visita",'Auditoria Documental'!$K$7:$K$1000,"<>Não avaliado",'Auditoria Documental'!$K$7:$K$1000,"<>")/COUNTIF('Lista Mestra'!$B$7:$B$59,"7. Checklist da visita"),0)) -> 0
A13: AUD-008 | B13: ESCOLA MUNICIPAL PROFESSORA LUCIA SOARES CASTRO | C13: {=IF(B13="","",IFERROR(INDEX('Cadastro Unidades'!$A$6:$A$222,MATCH(B13,'Cadastro Unidades'!$E$6:$E$222,0)),""))} -> DABEL | J13: =IF(A13="","",COUNTIF('Auditoria Documental'!$A$7:$A$1000,A13)) -> 0 | K13: =IF(A13="","",COUNTIFS('Auditoria Documental'!$A$7:$A$1000,A13,'Auditoria Documental'!$K$7:$K$1000,"<>Não avaliado",'Auditoria Documental'!$K$7:$K$1000,"<>")) -> 0 | L13: =IF(A13="","",IFERROR(SUMIFS('Auditoria Documental'!$N$7:$N$1000,'Auditoria Documental'!$A$7:$A$1000,A13)/SUMIFS('Auditoria Documental'!$M$7:$M$1000,'Auditoria Documental'!$A$7:$A$1000,A13),0)) -> 0 | M13: =IF(A13="","",COUNTIFS('Auditoria Documental'!$A$7:$A$1000,A13,'Auditoria Documental'!$J$7:$J$1000,3,'Auditoria Documental'!$K$7:$K$1000,"Não conforme")) -> 0 | N13: =IF(A13="","",IFERROR(COUNTIFS('Auditoria Documental'!$A$7:$A$1000,A13,'Auditoria Documental'!$G$7:$G$1000,"7. Checklist da visita",'Auditoria Documental'!$K$7:$K$1000,"<>Não avaliado",'Auditoria Documental'!$K$7:$K$1000,"<>")/COUNTIF('Lista Mestra'!$B$7:$B$59,"7. Checklist da visita"),0)) -> 0
A14: AUD-009 | B14: ESCOLA MUNICIPAL PROFESSORA RAIMUNDA LUCIA GUERREIRO | C14: {=IF(B14="","",IFERROR(INDEX('Cadastro Unidades'!$A$6:$A$222,MATCH(B14,'Cadastro Unidades'!$E$6:$E$222,0)),""))} -> DABEL | J14: =IF(A14="","",COUNTIF('Auditoria Documental'!$A$7:$A$1000,A14)) -> 0 | K14: =IF(A14="","",COUNTIFS('Auditoria Documental'!$A$7:$A$1000,A14,'Auditoria Documental'!$K$7:$K$1000,"<>Não avaliado",'Auditoria Documental'!$K$7:$K$1000,"<>")) -> 0 | L14: =IF(A14="","",IFERROR(SUMIFS('Auditoria Documental'!$N$7:$N$1000,'Auditoria Documental'!$A$7:$A$1000,A14)/SUMIFS('Auditoria Documental'!$M$7:$M$1000,'Auditoria Documental'!$A$7:$A$1000,A14),0)) -> 0 | M14: =IF(A14="","",COUNTIFS('Auditoria Documental'!$A$7:$A$1000,A14,'Auditoria Documental'!$J$7:$J$1000,3,'Auditoria Documental'!$K$7:$K$1000,"Não conforme")) -> 0 | N14: =IF(A14="","",IFERROR(COUNTIFS('Auditoria Documental'!$A$7:$A$1000,A14,'Auditoria Documental'!$G$7:$G$1000,"7. Checklist da visita",'Auditoria Documental'!$K$7:$K$1000,"<>Não avaliado",'Auditoria Documental'!$K$7:$K$1000,"<>")/COUNTIF('Lista Mestra'!$B$7:$B$59,"7. Checklist da visita"),0)) -> 0
A15: AUD-010 | B15: ESCOLA MUNICIPAL RUY DA SILVEIRA BRITTO | C15: {=IF(B15="","",IFERROR(INDEX('Cadastro Unidades'!$A$6:$A$222,MATCH(B15,'Cadastro Unidades'!$E$6:$E$222,0)),""))} -> DABEL | J15: =IF(A15="","",COUNTIF('Auditoria Documental'!$A$7:$A$1000,A15)) -> 0 | K15: =IF(A15="","",COUNTIFS('Auditoria Documental'!$A$7:$A$1000,A15,'Auditoria Documental'!$K$7:$K$1000,"<>Não avaliado",'Auditoria Documental'!$K$7:$K$1000,"<>")) -> 0 | L15: =IF(A15="","",IFERROR(SUMIFS('Auditoria Documental'!$N$7:$N$1000,'Auditoria Documental'!$A$7:$A$1000,A15)/SUMIFS('Auditoria Documental'!$M$7:$M$1000,'Auditoria Documental'!$A$7:$A$1000,A15),0)) -> 0 | M15: =IF(A15="","",COUNTIFS('Auditoria Documental'!$A$7:$A$1000,A15,'Auditoria Documental'!$J$7:$J$1000,3,'Auditoria Documental'!$K$7:$K$1000,"Não conforme")) -> 0 | N15: =IF(A15="","",IFERROR(COUNTIFS('Auditoria Documental'!$A$7:$A$1000,A15,'Auditoria Documental'!$G$7:$G$1000,"7. Checklist da visita",'Auditoria Documental'!$K$7:$K$1000,"<>Não avaliado",'Auditoria Documental'!$K$7:$K$1000,"<>")/COUNTIF('Lista Mestra'!$B$7:$B$59,"7. Checklist da visita"),0)) -> 0
A16: AUD-011 | B16: CENTRO DE REFERENCIA DE EDUCACAO INFANTIL PROF ORLANDO BITAR | C16: {=IF(B16="","",IFERROR(INDEX('Cadastro Unidades'!$A$6:$A$222,MATCH(B16,'Cadastro Unidades'!$E$6:$E$222,0)),""))} -> DABEL | J16: =IF(A16="","",COUNTIF('Auditoria Documental'!$A$7:$A$1000,A16)) -> 0 | K16: =IF(A16="","",COUNTIFS('Auditoria Documental'!$A$7:$A$1000,A16,'Auditoria Documental'!$K$7:$K$1000,"<>Não avaliado",'Auditoria Documental'!$K$7:$K$1000,"<>")) -> 0 | L16: =IF(A16="","",IFERROR(SUMIFS('Auditoria Documental'!$N$7:$N$1000,'Auditoria Documental'!$A$7:$A$1000,A16)/SUMIFS('Auditoria Documental'!$M$7:$M$1000,'Auditoria Documental'!$A$7:$A$1000,A16),0)) -> 0 | M16: =IF(A16="","",COUNTIFS('Auditoria Documental'!$A$7:$A$1000,A16,'Auditoria Documental'!$J$7:$J$1000,3,'Auditoria Documental'!$K$7:$K$1000,"Não conforme")) -> 0 | N16: =IF(A16="","",IFERROR(COUNTIFS('Auditoria Documental'!$A$7:$A$1000,A16,'Auditoria Documental'!$G$7:$G$1000,"7. Checklist da visita",'Auditoria Documental'!$K$7:$K$1000,"<>Não avaliado",'Auditoria Documental'!$K$7:$K$1000,"<>")/COUNTIF('Lista Mestra'!$B$7:$B$59,"7. Checklist da visita"),0)) -> 0
A17: AUD-012 | B17: INSTITUTO FELIPE SMALDONE BELEM | C17: {=IF(B17="","",IFERROR(INDEX('Cadastro Unidades'!$A$6:$A$222,MATCH(B17,'Cadastro Unidades'!$E$6:$E$222,0)),""))} -> DABEL | J17: =IF(A17="","",COUNTIF('Auditoria Documental'!$A$7:$A$1000,A17)) -> 0 | K17: =IF(A17="","",COUNTIFS('Auditoria Documental'!$A$7:$A$1000,A17,'Auditoria Documental'!$K$7:$K$1000,"<>Não avaliado",'Auditoria Documental'!$K$7:$K$1000,"<>")) -> 0 | L17: =IF(A17="","",IFERROR(SUMIFS('Auditoria Documental'!$N$7:$N$1000,'Auditoria Documental'!$A$7:$A$1000,A17)/SUMIFS('Auditoria Documental'!$M$7:$M$1000,'Auditoria Documental'!$A$7:$A$1000,A17),0)) -> 0 | M17: =IF(A17="","",COUNTIFS('Auditoria Documental'!$A$7:$A$1000,A17,'Auditoria Documental'!$J$7:$J$1000,3,'Auditoria Documental'!$K$7:$K$1000,"Não conforme")) -> 0 | N17: =IF(A17="","",IFERROR(COUNTIFS('Auditoria Documental'!$A$7:$A$1000,A17,'Auditoria Documental'!$G$7:$G$1000,"7. Checklist da visita",'Auditoria Documental'!$K$7:$K$1000,"<>Não avaliado",'Auditoria Documental'!$K$7:$K$1000,"<>")/COUNTIF('Lista Mestra'!$B$7:$B$59,"7. Checklist da visita"),0)) -> 0
A18: AUD-013 | B18: CRECHE CASA LAR CORDEIRINHO DE DEUS | C18: {=IF(B18="","",IFERROR(INDEX('Cadastro Unidades'!$A$6:$A$222,MATCH(B18,'Cadastro Unidades'!$E$6:$E$222,0)),""))} -> DABEL | J18: =IF(A18="","",COUNTIF('Auditoria Documental'!$A$7:$A$1000,A18)) -> 0 | K18: =IF(A18="","",COUNTIFS('Auditoria Documental'!$A$7:$A$1000,A18,'Auditoria Documental'!$K$7:$K$1000,"<>Não avaliado",'Auditoria Documental'!$K$7:$K$1000,"<>")) -> 0 | L18: =IF(A18="","",IFERROR(SUMIFS('Auditoria Documental'!$N$7:$N$1000,'Auditoria Documental'!$A$7:$A$1000,A18)/SUMIFS('Auditoria Documental'!$M$7:$M$1000,'Auditoria Documental'!$A$7:$A$1000,A18),0)) -> 0 | M18: =IF(A18="","",COUNTIFS('Auditoria Documental'!$A$7:$A$1000,A18,'Auditoria Documental'!$J$7:$J$1000,3,'Auditoria Documental'!$K$7:$K$1000,"Não conforme")) -> 0 | N18: =IF(A18="","",IFERROR(COUNTIFS('Auditoria Documental'!$A$7:$A$1000,A18,'Auditoria Documental'!$G$7:$G$1000,"7. Checklist da visita",'Auditoria Documental'!$K$7:$K$1000,"<>Não avaliado",'Auditoria Documental'!$K$7:$K$1000,"<>")/COUNTIF('Lista Mestra'!$B$7:$B$59,"7. Checklist da visita"),0)) -> 0
A19: AUD-014 | B19: ESCOLA MUNICIPAL BENVINDA DE FRANCA MESSIAS | C19: {=IF(B19="","",IFERROR(INDEX('Cadastro Unidades'!$A$6:$A$222,MATCH(B19,'Cadastro Unidades'!$E$6:$E$222,0)),""))} -> DABEL | J19: =IF(A19="","",COUNTIF('Auditoria Documental'!$A$7:$A$1000,A19)) -> 0 | K19: =IF(A19="","",COUNTIFS('Auditoria Documental'!$A$7:$A$1000,A19,'Auditoria Documental'!$K$7:$K$1000,"<>Não avaliado",'Auditoria Documental'!$K$7:$K$1000,"<>")) -> 0 | L19: =IF(A19="","",IFERROR(SUMIFS('Auditoria Documental'!$N$7:$N$1000,'Auditoria Documental'!$A$7:$A$1000,A19)/SUMIFS('Auditoria Documental'!$M$7:$M$1000,'Auditoria Documental'!$A$7:$A$1000,A19),0)) -> 0 | M19: =IF(A19="","",COUNTIFS('Auditoria Documental'!$A$7:$A$1000,A19,'Auditoria Documental'!$J$7:$J$1000,3,'Auditoria Documental'!$K$7:$K$1000,"Não conforme")) -> 0 | N19: =IF(A19="","",IFERROR(COUNTIFS('Auditoria Documental'!$A$7:$A$1000,A19,'Auditoria Documental'!$G$7:$G$1000,"7. Checklist da visita",'Auditoria Documental'!$K$7:$K$1000,"<>Não avaliado",'Auditoria Documental'!$K$7:$K$1000,"<>")/COUNTIF('Lista Mestra'!$B$7:$B$59,"7. Checklist da visita"),0)) -> 0
... A222: AUD-217 | B222: ESCOLA MUNICIPAL PERPETUO SOCORRO | C222: {=IF(B222="","",IFERROR(INDEX('Cadastro Unidades'!$A$6:$A$222,MATCH(B222,'Cadastro Unidades'!$E$6:$E$222,0)),""))} -> DASAC | J222: =IF(A222="","",COUNTIF('Auditoria Documental'!$A$7:$A$1000,A222)) -> 0 | K222: =IF(A222="","",COUNTIFS('Auditoria Documental'!$A$7:$A$1000,A222,'Auditoria Documental'!$K$7:$K$1000,"<>Não avaliado",'Auditoria Documental'!$K$7:$K$1000,"<>")) -> 0 | L222: =IF(A222="","",IFERROR(SUMIFS('Auditoria Documental'!$N$7:$N$1000,'Auditoria Documental'!$A$7:$A$1000,A222)/SUMIFS('Auditoria Documental'!$M$7:$M$1000,'Auditoria Documental'!$A$7:$A$1000,A222),0)) -> 0 | M222: =IF(A222="","",COUNTIFS('Auditoria Documental'!$A$7:$A$1000,A222,'Auditoria Documental'!$J$7:$J$1000,3,'Auditoria Documental'!$K$7:$K$1000,"Não conforme")) -> 0 | N222: =IF(A222="","",IFERROR(COUNTIFS('Auditoria Documental'!$A$7:$A$1000,A222,'Auditoria Documental'!$G$7:$G$1000,"7. Checklist da visita",'Auditoria Documental'!$K$7:$K$1000,"<>Não avaliado",'Auditoria Documental'!$K$7:$K$1000,"<>")/COUNTIF('Lista Mestra'!$B$7:$B$59,"7. Checklist da visita"),0)) -> 0

Sheet Auditoria Documental
A1: AUDITORIA DOCUMENTAL — CHECKLIST INTEGRAL
A2: Matriz de avaliação dos 53 registros do Checklist da CDE, com evidências, achados, pontuação e encaminhamento corretivo
A4: Preencha o Plano de Auditoria e classifique todos os itens do bloco AUD-0001. Para uma nova unidade, copie o bloco completo, altere o ID e ajuste o vínculo ao registro correspondente do plano.
A6: ID auditoria | B6: Data | C6: Unidade | D6: Distrito | E6: Auditor(a) | F6: Bairro | G6: Seção do Checklist | H6: Documento/item | I6: Evidência esperada | J6: Peso | K6: Situação | L6: Evidência/localização | M6: Peso aplicável | N6: Pontos | O6: Índice do item | P6: Achado/observação | Q6: Requer ação? | R6: Prazo | S6: Responsável | T6: Situação da ação
A7: AUD-0001 | B7: =IF('Plano de Auditoria'!$G$6<>"",'Plano de Auditoria'!$G$6,IF('Plano de Auditoria'!$F$6="","",'Plano de Auditoria'!$F$6)) | C7: =IF('Plano de Auditoria'!$B$6="","",'Plano de Auditoria'!$B$6) -> ESCOLA MUNICIPAL PROFESSORA MARIA AUXILIADORA MARTINS GONCALVES | D7: =IF('Plano de Auditoria'!$C$6="","",'Plano de Auditoria'!$C$6) -> DABEL | E7: =IF('Plano de Auditoria'!$H$6="","",'Plano de Auditoria'!$H$6) | F7: MARCO | G7: 1. Documentos institucionais | H7: Ato de criação da escola | I7: Ato integral, legível e disponível para conferência. | J7: 3 | K7: Não avaliado | M7: =IF(OR(K7="Não se aplica",K7="",J7=0),0,J7) -> 3 | N7: =IF(K7="Conforme",M7,IF(K7="Parcialmente conforme",M7*0.5,0)) -> 0 | O7: =IF(M7=0,"",N7/M7) -> 0 | Q7: Não
A8: AUD-0001 | B8: =IF('Plano de Auditoria'!$G$6<>"",'Plano de Auditoria'!$G$6,IF('Plano de Auditoria'!$F$6="","",'Plano de Auditoria'!$F$6)) | C8: =IF('Plano de Auditoria'!$B$6="","",'Plano de Auditoria'!$B$6) -> ESCOLA MUNICIPAL PROFESSORA MARIA AUXILIADORA MARTINS GONCALVES | D8: =IF('Plano de Auditoria'!$C$6="","",'Plano de Auditoria'!$C$6) -> DABEL | E8: =IF('Plano de Auditoria'!$H$6="","",'Plano de Auditoria'!$H$6) | F8: MARCO | G8: 1. Documentos institucionais | H8: Recibo do Censo Escolar (Autorização) | I8: Recibo do Censo Escolar e comprovantes correspondentes. | J8: 2 | K8: Não avaliado | M8: =IF(OR(K8="Não se aplica",K8="",J8=0),0,J8) -> 2 | N8: =IF(K8="Conforme",M8,IF(K8="Parcialmente conforme",M8*0.5,0)) -> 0 | O8: =IF(M8=0,"",N8/M8) -> 0 | Q8: Não
A9: AUD-0001 | B9: =IF('Plano de Auditoria'!$G$6<>"",'Plano de Auditoria'!$G$6,IF('Plano de Auditoria'!$F$6="","",'Plano de Auditoria'!$F$6)) | C9: =IF('Plano de Auditoria'!$B$6="","",'Plano de Auditoria'!$B$6) -> ESCOLA MUNICIPAL PROFESSORA MARIA AUXILIADORA MARTINS GONCALVES | D9: =IF('Plano de Auditoria'!$C$6="","",'Plano de Auditoria'!$C$6) -> DABEL | E9: =IF('Plano de Auditoria'!$H$6="","",'Plano de Auditoria'!$H$6) | F9: MARCO | G9: 1. Documentos institucionais | H9: Ato de autorização, credenciamento ou reconhecimento | I9: Ato completo, vigente e compatível com as etapas/modalidades ofertadas. | J9: 3 | K9: Não avaliado | M9: =IF(OR(K9="Não se aplica",K9="",J9=0),0,J9) -> 3 | N9: =IF(K9="Conforme",M9,IF(K9="Parcialmente conforme",M9*0.5,0)) -> 0 | O9: =IF(M9=0,"",N9/M9) -> 0 | Q9: Não
A10: AUD-0001 | B10: =IF('Plano de Auditoria'!$G$6<>"",'Plano de Auditoria'!$G$6,IF('Plano de Auditoria'!$F$6="","",'Plano de Auditoria'!$F$6)) | C10: =IF('Plano de Auditoria'!$B$6="","",'Plano de Auditoria'!$B$6) -> ESCOLA MUNICIPAL PROFESSORA MARIA AUXILIADORA MARTINS GONCALVES | D10: =IF('Plano de Auditoria'!$C$6="","",'Plano de Auditoria'!$C$6) -> DABEL | E10: =IF('Plano de Auditoria'!$H$6="","",'Plano de Auditoria'!$H$6) | F10: MARCO | G10: 1. Documentos institucionais | H10: Regimento Escolar atualizado | I10: Versão atualizada, aprovada, datada e disponível. | J10: 2 | K10: Não avaliado | M10: =IF(OR(K10="Não se aplica",K10="",J10=0),0,J10) -> 2 | N10: =IF(K10="Conforme",M10,IF(K10="Parcialmente conforme",M10*0.5,0)) -> 0 | O10: =IF(M10=0,"",N10/M10) -> 0 | Q10: Não
A11: AUD-0001 | B11: =IF('Plano de Auditoria'!$G$6<>"",'Plano de Auditoria'!$G$6,IF('Plano de Auditoria'!$F$6="","",'Plano de Auditoria'!$F$6)) | C11: =IF('Plano de Auditoria'!$B$6="","",'Plano de Auditoria'!$B$6) -> ESCOLA MUNICIPAL PROFESSORA MARIA AUXILIADORA MARTINS GONCALVES | D11: =IF('Plano de Auditoria'!$C$6="","",'Plano de Auditoria'!$C$6) -> DABEL | E11: =IF('Plano de Auditoria'!$H$6="","",'Plano de Auditoria'!$H$6) | F11: MARCO | G11: 1. Documentos institucionais | H11: Projeto Político-Pedagógico (PPP) | I11: PPP atualizado, aprovado e disponível. | J11: 2 | K11: Não avaliado | M11: =IF(OR(K11="Não se aplica",K11="",J11=0),0,J11) -> 2 | N11: =IF(K11="Conforme",M11,IF(K11="Parcialmente conforme",M11*0.5,0)) -> 0 | O11: =IF(M11=0,"",N11/M11) -> 0 | Q11: Não
A12: AUD-0001 | B12: =IF('Plano de Auditoria'!$G$6<>"",'Plano de Auditoria'!$G$6,IF('Plano de Auditoria'!$F$6="","",'Plano de Auditoria'!$F$6)) | C12: =IF('Plano de Auditoria'!$B$6="","",'Plano de Auditoria'!$B$6) -> ESCOLA MUNICIPAL PROFESSORA MARIA AUXILIADORA MARTINS GONCALVES | D12: =IF('Plano de Auditoria'!$C$6="","",'Plano de Auditoria'!$C$6) -> DABEL | E12: =IF('Plano de Auditoria'!$H$6="","",'Plano de Auditoria'!$H$6) | F12: MARCO | G12: 1. Documentos institucionais | H12: Calendário Escolar vigente | I12: Calendário acessível no SIGA: Administração > Calendário Escolar > Acessar Calendário. | J12: 2 | K12: Não avaliado | M12: =IF(OR(K12="Não se aplica",K12="",J12=0),0,J12) -> 2 | N12: =IF(K12="Conforme",M12,IF(K12="Parcialmente conforme",M12*0.5,0)) -> 0 | O12: =IF(M12=0,"",N12/M12) -> 0 | Q12: Não
A13: AUD-0001 | B13: =IF('Plano de Auditoria'!$G$6<>"",'Plano de Auditoria'!$G$6,IF('Plano de Auditoria'!$F$6="","",'Plano de Auditoria'!$F$6)) | C13: =IF('Plano de Auditoria'!$B$6="","",'Plano de Auditoria'!$B$6) -> ESCOLA MUNICIPAL PROFESSORA MARIA AUXILIADORA MARTINS GONCALVES | D13: =IF('Plano de Auditoria'!$C$6="","",'Plano de Auditoria'!$C$6) -> DABEL | E13: =IF('Plano de Auditoria'!$H$6="","",'Plano de Auditoria'!$H$6) | F13: MARCO | G13: 1. Documentos institucionais | H13: Matriz curricular, inclusive cursos técnicos | I13: Matriz vigente por etapa/modalidade, com componentes e cargas horárias. | J13: 3 | K13: Não avaliado | M13: =IF(OR(K13="Não se aplica",K13="",J13=0),0,J13) -> 3 | N13: =IF(K13="Conforme",M13,IF(K13="Parcialmente conforme",M13*0.5,0)) -> 0 | O13: =IF(M13=0,"",N13/M13) -> 0 | Q13: Não
A14: AUD-0001 | B14: =IF('Plano de Auditoria'!$G$6<>"",'Plano de Auditoria'!$G$6,IF('Plano de Auditoria'!$F$6="","",'Plano de Auditoria'!$F$6)) | C14: =IF('Plano de Auditoria'!$B$6="","",'Plano de Auditoria'!$B$6) -> ESCOLA MUNICIPAL PROFESSORA MARIA AUXILIADORA MARTINS GONCALVES | D14: =IF('Plano de Auditoria'!$C$6="","",'Plano de Auditoria'!$C$6) -> DABEL | E14: =IF('Plano de Auditoria'!$H$6="","",'Plano de Auditoria'!$H$6) | F14: MARCO | G14: 2. Secretaria escolar | H14: Livro de Matrícula | I14: Livro completo, atualizado e com termos de abertura e encerramento. | J14: 3 | K14: Não avaliado | M14: =IF(OR(K14="Não se aplica",K14="",J14=0),0,J14) -> 3 | N14: =IF(K14="Conforme",M14,IF(K14="Parcialmente conforme",M14*0.5,0)) -> 0 | O14: =IF(M14=0,"",N14/M14) -> 0 | Q14: Não
A15: AUD-0001 | B15: =IF('Plano de Auditoria'!$G$6<>"",'Plano de Auditoria'!$G$6,IF('Plano de Auditoria'!$F$6="","",'Plano de Auditoria'!$F$6)) | C15: =IF('Plano de Auditoria'!$B$6="","",'Plano de Auditoria'!$B$6) -> ESCOLA MUNICIPAL PROFESSORA MARIA AUXILIADORA MARTINS GONCALVES | D15: =IF('Plano de Auditoria'!$C$6="","",'Plano de Auditoria'!$C$6) -> DABEL | E15: =IF('Plano de Auditoria'!$H$6="","",'Plano de Auditoria'!$H$6) | F15: MARCO | G15: 2. Secretaria escolar | H15: Livro de Atas — resultados finais, Conselho de Classe, reuniões e outros | I15: Livros completos, sequenciais, datados e assinados. | J15: 3 | K15: Não avaliado | M15: =IF(OR(K15="Não se aplica",K15="",J15=0),0,J15) -> 3 | N15: =IF(K15="Conforme",M15,IF(K15="Parcialmente conforme",M15*0.5,0)) -> 0 | O15: =IF(M15=0,"",N15/M15) -> 0 | Q15: Não
A16: AUD-0001 | B16: =IF('Plano de Auditoria'!$G$6<>"",'Plano de Auditoria'!$G$6,IF('Plano de Auditoria'!$F$6="","",'Plano de Auditoria'!$F$6)) | C16: =IF('Plano de Auditoria'!$B$6="","",'Plano de Auditoria'!$B$6) -> ESCOLA MUNICIPAL PROFESSORA MARIA AUXILIADORA MARTINS GONCALVES | D16: =IF('Plano de Auditoria'!$C$6="","",'Plano de Auditoria'!$C$6) -> DABEL | E16: =IF('Plano de Auditoria'!$H$6="","",'Plano de Auditoria'!$H$6) | F16: MARCO | G16: 2. Secretaria escolar | H16: Livro de Registro de Diplomas e Certificados, quando aplicável | I16: Registro sequencial, íntegro e rastreável dos documentos expedidos. | J16: 3 | K16: Não avaliado | M16: =IF(OR(K16="Não se aplica",K16="",J16=0),0,J16) -> 3 | N16: =IF(K16="Conforme",M16,IF(K16="Parcialmente conforme",M16*0.5,0)) -> 0 | O16: =IF(M16=0,"",N16/M16) -> 0 | Q16: Não
A17: AUD-0001 | B17: =IF('Plano de Auditoria'!$G$6<>"",'Plano de Auditoria'!$G$6,IF('Plano de Auditoria'!$F$6="","",'Plano de Auditoria'!$F$6)) | C17: =IF('Plano de Auditoria'!$B$6="","",'Plano de Auditoria'!$B$6) -> ESCOLA MUNICIPAL PROFESSORA MARIA AUXILIADORA MARTINS GONCALVES | D17: =IF('Plano de Auditoria'!$C$6="","",'Plano de Auditoria'!$C$6) -> DABEL | E17: =IF('Plano de Auditoria'!$H$6="","",'Plano de Auditoria'!$H$6) | F17: MARCO | G17: 2. Secretaria escolar | H17: Protocolos de entrada e saída de documentos | I17: Registros cronológicos de recebimento, tramitação e entrega. | J17: 2 | K17: Não avaliado | M17: =IF(OR(K17="Não se aplica",K17="",J17=0),0,J17) -> 2 | N17: =IF(K17="Conforme",M17,IF(K17="Parcialmente conforme",M17*0.5,0)) -> 0 | O17: =IF(M17=0,"",N17/M17) -> 0 | Q17: Não
A18: AUD-0001 | B18: =IF('Plano de Auditoria'!$G$6<>"",'Plano de Auditoria'!$G$6,IF('Plano de Auditoria'!$F$6="","",'Plano de Auditoria'!$F$6)) | C18: =IF('Plano de Auditoria'!$B$6="","",'Plano de Auditoria'!$B$6) -> ESCOLA MUNICIPAL PROFESSORA MARIA AUXILIADORA MARTINS GONCALVES | D18: =IF('Plano de Auditoria'!$C$6="","",'Plano de Auditoria'!$C$6) -> DABEL | E18: =IF('Plano de Auditoria'!$H$6="","",'Plano de Auditoria'!$H$6) | F18: MARCO | G18: 2. Secretaria escolar | H18: Arquivo ativo e arquivo permanente organizados | I18: Pastas classificadas, preservadas, localizáveis e com acesso controlado. | J18: 3 | K18: Não avaliado | M18: =IF(OR(K18="Não se aplica",K18="",J18=0),0,J18) -> 3 | N18: =IF(K18="Conforme",M18,IF(K18="Parcialmente conforme",M18*0.5,0)) -> 0 | O18: =IF(M18=0,"",N18/M18) -> 0 | Q18: Não
... A59: AUD-0001 | B59: =IF('Plano de Auditoria'!$G$6<>"",'Plano de Auditoria'!$G$6,IF('Plano de Auditoria'!$F$6="","",'Plano de Auditoria'!$F$6)) | C59: =IF('Plano de Auditoria'!$B$6="","",'Plano de Auditoria'!$B$6) -> ESCOLA MUNICIPAL PROFESSORA MARIA AUXILIADORA MARTINS GONCALVES | D59: =IF('Plano de Auditoria'!$C$6="","",'Plano de Auditoria'!$C$6) -> DABEL | E59: =IF('Plano de Auditoria'!$H$6="","",'Plano de Auditoria'!$H$6) | F59: MARCO | G59: 7. Checklist da visita | H59: Dados do Censo Escolar conferidos | I59: Síntese de conferência da visita. | J59: 0 | K59: Não avaliado | M59: =IF(OR(K59="Não se aplica",K59="",J59=0),0,J59) -> 0 | N59: =IF(K59="Conforme",M59,IF(K59="Parcialmente conforme",M59*0.5,0)) -> 0 | O59: =IF(M59=0,"",N59/M59) | Q59: Não
B60: =IF('Plano de Auditoria'!$G$6<>"",'Plano de Auditoria'!$G$6,IF('Plano de Auditoria'!$F$6="","",'Plano de Auditoria'!$F$6)) | E60: =IF('Plano de Auditoria'!$H$6="","",'Plano de Auditoria'!$H$6) | M60: =IF(OR(K60="Não se aplica",K60="",J60=0),0,J60) -> 0 | N60: =IF(K60="Conforme",M60,IF(K60="Parcialmente conforme",M60*0.5,0)) -> 0 | O60: =IF(M60=0,"",N60/M60)

Sheet Checklist da Visita
A1: CHECKLIST PARA A VISITA TÉCNICA
A2: Síntese operacional dos 12 itens finais do Checklist da Coordenadoria de Documentação Escolar
A4: Auditoria | C4: ='Plano de Auditoria'!A7 -> AUD-002 | E4: Data da visita | G4: =IF('Plano de Auditoria'!G6<>"",'Plano de Auditoria'!G6,IF('Plano de Auditoria'!F6="","",'Plano de Auditoria'!F6))
A5: Unidade | G5: Distrito | H5: =IF('Plano de Auditoria'!C6="","",'Plano de Auditoria'!C6) -> DABEL
A6: Auditor(a)/equipe | C6: =IF('Plano de Auditoria'!H6="","",'Plano de Auditoria'!H6) | G6: Conclusão | H6: ='Plano de Auditoria'!N6 -> 0
A8: Nº | B8: Item do Checklist para a visita | C8: Situação | D8: Evidência/localização | E8: Achado/observação | F8: Requer ação? | G8: Responsável | H8: Prazo
A9: 1 | B9: Regimento Escolar atualizado | C9: ='Auditoria Documental'!K48 -> Não avaliado | D9: =IF('Auditoria Documental'!L48="","",'Auditoria Documental'!L48) | E9: =IF('Auditoria Documental'!P48="","",'Auditoria Documental'!P48) | F9: ='Auditoria Documental'!Q48 -> Não | G9: =IF('Auditoria Documental'!S48="","",'Auditoria Documental'!S48) | H9: =IF('Auditoria Documental'!R48="","",'Auditoria Documental'!R48)
A10: 2 | B10: PPP atualizado | C10: ='Auditoria Documental'!K49 -> Não avaliado | D10: =IF('Auditoria Documental'!L49="","",'Auditoria Documental'!L49) | E10: =IF('Auditoria Documental'!P49="","",'Auditoria Documental'!P49) | F10: ='Auditoria Documental'!Q49 -> Não | G10: =IF('Auditoria Documental'!S49="","",'Auditoria Documental'!S49) | H10: =IF('Auditoria Documental'!R49="","",'Auditoria Documental'!R49)
A11: 3 | B11: Calendário Escolar aprovado | C11: ='Auditoria Documental'!K50 -> Não avaliado | D11: =IF('Auditoria Documental'!L50="","",'Auditoria Documental'!L50) | E11: =IF('Auditoria Documental'!P50="","",'Auditoria Documental'!P50) | F11: ='Auditoria Documental'!Q50 -> Não | G11: =IF('Auditoria Documental'!S50="","",'Auditoria Documental'!S50) | H11: =IF('Auditoria Documental'!R50="","",'Auditoria Documental'!R50)
A12: 4 | B12: Livros oficiais completos e assinados | C12: ='Auditoria Documental'!K51 -> Não avaliado | D12: =IF('Auditoria Documental'!L51="","",'Auditoria Documental'!L51) | E12: =IF('Auditoria Documental'!P51="","",'Auditoria Documental'!P51) | F12: ='Auditoria Documental'!Q51 -> Não | G12: =IF('Auditoria Documental'!S51="","",'Auditoria Documental'!S51) | H12: =IF('Auditoria Documental'!R51="","",'Auditoria Documental'!R51)
A13: 5 | B13: Diários de Classe atualizados | C13: ='Auditoria Documental'!K52 -> Não avaliado | D13: =IF('Auditoria Documental'!L52="","",'Auditoria Documental'!L52) | E13: =IF('Auditoria Documental'!P52="","",'Auditoria Documental'!P52) | F13: ='Auditoria Documental'!Q52 -> Não | G13: =IF('Auditoria Documental'!S52="","",'Auditoria Documental'!S52) | H13: =IF('Auditoria Documental'!R52="","",'Auditoria Documental'!R52)
A14: 6 | B14: Atas de resultados finais e conselhos | C14: ='Auditoria Documental'!K53 -> Não avaliado | D14: =IF('Auditoria Documental'!L53="","",'Auditoria Documental'!L53) | E14: =IF('Auditoria Documental'!P53="","",'Auditoria Documental'!P53) | F14: ='Auditoria Documental'!Q53 -> Não | G14: =IF('Auditoria Documental'!S53="","",'Auditoria Documental'!S53) | H14: =IF('Auditoria Documental'!R53="","",'Auditoria Documental'!R53)
A15: 7 | B15: Históricos escolares organizados | C15: ='Auditoria Documental'!K54 -> Não avaliado | D15: =IF('Auditoria Documental'!L54="","",'Auditoria Documental'!L54) | E15: =IF('Auditoria Documental'!P54="","",'Auditoria Documental'!P54) | F15: ='Auditoria Documental'!Q54 -> Não | G15: =IF('Auditoria Documental'!S54="","",'Auditoria Documental'!S54) | H15: =IF('Auditoria Documental'!R54="","",'Auditoria Documental'!R54)
A16: 8 | B16: Fichas de matrícula completas | C16: ='Auditoria Documental'!K55 -> Não avaliado | D16: =IF('Auditoria Documental'!L55="","",'Auditoria Documental'!L55) | E16: =IF('Auditoria Documental'!P55="","",'Auditoria Documental'!P55) | F16: ='Auditoria Documental'!Q55 -> Não | G16: =IF('Auditoria Documental'!S55="","",'Auditoria Documental'!S55) | H16: =IF('Auditoria Documental'!R55="","",'Auditoria Documental'!R55)
